<?xml version="1.0" ?>

<robot name="restore">

  <link name="base_link"/>

  <joint name="fixed" type="fixed">
    <parent link="base_link"/>
    <child link="link1"/>
  </joint>

  <link name="link1">

    <visual>
      <origin rpy="0 0 0" xyz="0 0 0"/>
      <geometry>
        <mesh filename="package://meshes_restore/link1.stl" scale="0.001 0.001 0.001"/>
      </geometry>
    </visual>

    <collision>
      <geometry>
        <mesh filename="package://meshes_restore/link1.stl" scale="0.001 0.001 0.001"/>
      </geometry>
      <origin rpy="0 0 0" xyz="0 0 0"/>
    </collision>

    <inertial>
      <mass value="30.0"/>
      <origin rpy="0 0 0" xyz="0 0 0"/>
      <inertia ixx="5" ixy="0.0" ixz="0.0" iyy="5" iyz="0.0" izz="20"/>
    </inertial>

  </link>

  <joint name="joint0" type="revolute">
    <parent link="link1"/>
    <child link="link2"/>
    <origin rpy="0 0 0" xyz="0 0 0.35"/>
    <axis xyz="0 0 1"/>
    <dynamics damping="10"/>
    <limit effort="1300" lower="-3" upper="3" velocity="0.2"/>
  </joint>

  <link name="link2">
    <visual>
      <origin rpy="-1.57 0 0" xyz="0 0 0"/>
      <geometry>
        <mesh filename="package://meshes_restore/link2.stl" scale="0.001 0.001 0.001"/>
      </geometry>
    </visual>

    <collision>
      <origin rpy="-1.57 0 0" xyz="0 0 0"/>
      <geometry>
        <mesh filename="package://meshes_restore/link2.stl" scale="0.001 0.001 0.001"/>
      </geometry>
    </collision>

    <inertial>
      <mass value="20"/>
      <origin rpy="1.57 0 0" xyz="0 0 0"/>
      <inertia ixx="0.3" ixy="0" ixz="0" iyy="0.1" iyz="0" izz="10"/>
    </inertial>

  </link>

  <joint name="joint1" type="revolute">
    <parent link="link2"/>
    <child link="link3"/>
    <origin rpy="1.57 0 0" xyz="0 0.25 0"/>
    <axis xyz="0 0 1"/>
    <dynamics damping="10"/>
    <limit effort="1300" lower="-3" upper="3" velocity="0.2"/>
  </joint>

  <link name="link3">

    <visual>
      <origin rpy="-1.57 0 0" xyz="0 0 0.0"/>
      <geometry>
        <mesh filename="package://meshes_restore/link3.stl" scale="0.001 0.001 0.001"/>
      </geometry>
    </visual>

    <collision>
      <origin rpy="-1.57 0 0" xyz="0 0 0.0"/>
      <geometry>
        <mesh filename="package://meshes_restore/link3.stl" scale="0.001 0.001 0.001"/>
      </geometry>
    </collision>

    <inertial>
      <mass value="15"/>
      <origin rpy="-1.57 0 0" xyz="0 0 0"/>
      <inertia ixx="0.2" ixy="0" ixz="0" iyy="0.1" iyz="0" izz="10"/>
    </inertial>

  </link>

  <joint name="joint2" type="revolute">
    <parent link="link3"/>
    <child link="link4"/>
    <origin rpy="-1.57 0 0" xyz="0 1 0"/>
    <axis xyz="0 0 1"/>
    <dynamics damping="5"/>
    <limit effort="500" lower="-3.1" upper="2.8" velocity="0.3"/>
  </joint>

  <link name="link4">

    <visual>
      <origin rpy="1.57 0 0" xyz="0 0 0"/>
      <geometry>
        <mesh filename="package://meshes_restore/link4.stl" scale="0.001 0.001 0.001"/>
      </geometry>
    </visual>

    <collision>
      <origin rpy="1.57 0 0" xyz="0 0 0"/>
      <geometry>
        <mesh filename="package://meshes_restore/link4.stl" scale="0.001 0.001 0.001"/>
      </geometry>
    </collision>

    <inertial>
      <mass value="15"/>
      <origin rpy="-1.57 0 0" xyz="0 0 0"/>
      <inertia ixx="2" ixy="0" ixz="0" iyy="0.1" iyz="0" izz="10"/>
    </inertial>

  </link>

  <joint name="joint3" type="revolute">
    <parent link="link4"/>
    <child link="link5"/>
    <origin rpy="1.57 0 0" xyz="0 -0.2 0"/>
    <axis xyz="0 0 1"/>
    <dynamics damping="1000"/>
    <limit effort="500" lower="-3.1" upper="2.7" velocity="0.3"/>

  </joint>

  <link name="link5">

    <visual>
      <origin rpy="-1.57 0 0" xyz="0 0 0.0"/>
      <geometry>
        <mesh filename="package://meshes_restore/link5.stl" scale="0.001 0.001 0.001"/>
      </geometry>
    </visual>

    <collision>
      <origin rpy="-1.57 0 0" xyz="0 0 0.0"/>
      <geometry>
        <mesh filename="package://meshes_restore/link5.stl" scale="0.001 0.001 0.001"/>
      </geometry>
    </collision>

    <inertial>
      <mass value="8"/>
      <origin rpy="-1.57 0 0" xyz="0 0 0"/>
      <inertia ixx="0.1" ixy="0" ixz="0" iyy="2" iyz="0" izz="3"/>
    </inertial>

  </link>

  <joint name="joint4" type="revolute">
    <parent link="link5"/>
    <child link="link6"/>
    <origin rpy="-1.57 0 0" xyz="0 1 0"/>
    <axis xyz="0 0 1"/>
    <dynamics damping="30"/>
    <limit effort="100" lower="-4." upper="1.5" velocity="0.400"/>
  </joint>

  <link name="link6">

    <visual>
      <origin rpy="-1.57 0 0" xyz="0 0.0 0"/>
      <geometry>
        <mesh filename="package://meshes_restore/link6.stl" scale="0.001 0.001 0.001"/>
      </geometry>
    </visual>

    <collision>
      <origin rpy="-1.57 0 0" xyz="0 0.0 0"/>
      <geometry>
        <mesh filename="package://meshes_restore/link6.stl" scale="0.001 0.001 0.001"/>
      </geometry>
    </collision>

    <inertial>
      <mass value="6"/>
      <origin rpy="1.57 0 0" xyz="0 0 0"/>
      <inertia ixx="1" ixy="0" ixz="0" iyy="1" iyz="0" izz="1"/>
    </inertial>

  </link>

  <joint name="joint5" type="revolute">
    <parent link="link6"/>
    <child link="link7"/>
    <origin rpy="1.57 0 0" xyz="0 0 0"/>
    <axis xyz="0 0 1"/>
    <dynamics damping="30"/>
    <limit effort="100" lower="-3" upper="3" velocity="0.5"/>
  </joint>

  <link name="link7">
    <visual>
      <origin rpy="0 0 0" xyz="0 0 0"/>
      <geometry>
        <mesh filename="package://meshes_restore/link7.stl" scale="0.001 0.001 0.001"/>
      </geometry>
    </visual>

    <inertial>
      <mass value="4"/>
      <origin rpy="-1.57 0 0" xyz="0 0 0"/>
      <inertia ixx="0.03" ixy="0" ixz="0" iyy="1" iyz="0" izz="1"/>
    </inertial>

  </link>

  <joint name="joint6" type="revolute">
    <parent link="link7"/>
    <child link="link8"/>
    <origin rpy="-1.57 0 0" xyz="0 0.2 0"/>
    <axis xyz="0 0 1"/>
    <dynamics damping="15"/>
    <limit effort="70" lower="-4.5" upper="1.2" velocity="0.4"/>
  </joint>

  <link name="link8">

    <visual>
      <origin rpy="3.14 0 0" xyz="0 0 -.065"/>
      <geometry>
        <mesh filename="package://meshes_restore/link8.stl" scale="0.001 0.001 0.001"/>
      </geometry>
    </visual>

    <inertial>
      <mass value="4"/>
      <origin rpy="0 0 0" xyz="0 0 0"/>
      <inertia ixx="0.03" ixy="0" ixz="0" iyy="0.03" iyz="0" izz="1"/>
    </inertial>

  </link>

</robot>